Workbook

Sheet Self_Assessment
A1: Individual Self Assessment on Axes of People-or-Task and Execution-or-Vision | I1: From Strengthsfinder 2
A2: © Bob Warfield 2015-2020
I3: https://www.amazon.com.au/StrengthsFinder-2-0-Tom-Rath/dp/159562015X/
B4: The purpose of this self-assessment is to begin the process of considering your own preferences and talents, as well as those of
B5: your team members and other stakeholders.
I6: Theme | J6: People who are especially talented in the … theme:
B7: In this context "strength" refers to your natural inclination for a type of activity. When you are working on a task | I7: Achiever | J7: have a great deal of stamina and work hard. They take great satisfaction from being busy and productive. | M7: =Numbers!E6 -> 0.875 | N7: =Numbers!F6 -> -0.87499996
B8: that uses your natural strength, you | I8: Activator | J8: can make things happen by turning thoughts into action. They are often impatient. | M8: =Numbers!E7 -> 0.70000004 | N8: =Numbers!F7 -> -0.59999996
B9: - enjoy your work | I9: Adaptability | J9: prefer to “go with the flow.” They tend to be “now” people who take things as they come and discover the future one day at a time. | M9: =Numbers!E8 -> 0.34999998 | N9: =Numbers!F8 -> -0.29999995
B10: - find it easy to learn and improve | I10: Analytical | J10: search for reasons and causes. They have the ability to think about all the factors that might affect a situation. | M10: =Numbers!E9 -> 0.70000004 | N10: =Numbers!F9 -> 0.4
B11: - lose track of time - you have to be called to dinner to leave your work | I11: Arranger | J11: can organize, but they also have a flexibility that complements this ability. They like to figure out how all of the pieces and resources can be arranged for maximum productivity. | M11: =Numbers!E10 -> -0.12000001 | N11: =Numbers!F10 -> -0.34999999
B12: Wouldn't it be great if your job was always like that! | I12: Belief | J12: have certain core values that are unchanging. Out of these values emerges a defined purpose for their life. | M12: =Numbers!E11 -> -0.87500002 | N12: =Numbers!F11 -> 0.87499999
I13: Command | J13: have presence. They can take control of a situation and make decisions. | M13: =Numbers!E12 -> 0.10000001 | N13: =Numbers!F12 -> -0.84545455
B14: The results are expressed as an orientation towards people or tasks (horizontal axis) and vision or execution (vertical axis). | I14: Communication | J14: generally find it easy to put their thoughts into words. They are good conversationalists and presenters. | M14: =Numbers!E13 -> -0.39999998 | N14: =Numbers!F13 -> -0.24545453
B15: Possible matches to the strengths in the book "Strengthsfinder 2" are included as well as some likely and unlikely occupations. | I15: Competition | J15: measure their progress against the performance of others. They strive to win first place and revel in contests. | M15: =Numbers!E14 -> 0.19090907 | N15: =Numbers!F14 -> 0.40909094
B16: For more information consult the book - link shown above. | I16: Connectedness | J16: have faith in the links between all things. They believe there are few coincidences and that almost every event has a reason. | M16: =Numbers!E15 -> -0.8 | N16: =Numbers!F15 -> 0.69999999
I17: Consistency | J17: are keenly aware of the need to treat people the same. They try to treat everyone in the world with consistency by setting up clear rules and adhering to them. | M17: =Numbers!E16 -> -0.3 | N17: =Numbers!F16 -> -0.049999991
B18: What is the first thing you do when you come in to work? | I18: Context | J18: enjoy thinking about the past. They understand the present by researching its history. | M18: =Numbers!E17 -> 0.15000003 | N18: =Numbers!F17 -> -0.35454542
B19: - If you said "smile and greet all my team mates" you may be people-oriented. | I19: Deliberative | J19: are best described by the serious care they take in making decisions or choices. They anticipate the obstacles. | M19: =Numbers!E18 -> 0.10000001 | N19: =Numbers!F18 -> 0.19090908
B20: - If you said "check my to-do list" you might be more task-oriented. | I20: Developer | J20: recognize and cultivate the potential in others. They spot the signs of each small improvement and derive satisfaction from these improvements. | M20: =Numbers!E19 -> -0.30000005 | N20: =Numbers!F19 -> 0.30000001
I21: Discipline | J21: enjoy routine and structure. Their world is best de- scribed by the order they create. | M21: =Numbers!E20 -> 0.69999999 | N21: =Numbers!F20 -> -0.29999996
B22: Would you prefer to be fixing today's problems, or planning next year's work? | I22: Empathy | J22: can sense the feelings of other people by imagining themselves in others’ lives or others’ situations. | M22: =Numbers!E21 -> -0.44999996 | N22: =Numbers!F21 -> 0.08181817
B23: - If you prefer today's problems you may be execution-oriented | I23: Focus | J23: can take a direction, follow through, and make the corrections necessary to stay on track. They prioritize, then act. | M23: =Numbers!E22 -> 0.20000001 | N23: =Numbers!F22 -> -0.081818176
B24: - Planning next year's work is more a vision-oriented task | I24: Futuristic | J24: are inspired by the future and what could be. They inspire others with their visions of the future. | M24: =Numbers!E23 -> 0.80000002 | N24: =Numbers!F23 -> 0.70000001
I25: Harmony | J25: look for consensus. They don’t enjoy conflict; rather, they seek areas of agreement. | M25: =Numbers!E24 -> -0.57272728 | N25: =Numbers!F24 -> -0.60000004
B26: The test below is provided for entertainment and food for thought - it is not intended as a scientific test! | I26: Ideation | J26: are fascinated by ideas. They are able to find connections between seemingly disparate phenomena. | M26: =Numbers!E25 -> 0.51818185 | N26: =Numbers!F25 -> 0.57272725
B27: Feel free to modify your own results according to your insight and experience. | D27: People or Task | E27: Execution or Vision | I27: Includer | J27: are accepting of others. They show awareness of those who feel left out, and make an effort to include them. | M27: =Numbers!E26 -> -0.40000003 | N27: =Numbers!F26 -> -0.74999997
D28: (People: -100%) | E28: (Execution: -100%) | I28: Individualization | J28: are intrigued with the unique qualities of each person. They have a gift for figuring out how people who are different can work together productively. | M28: =Numbers!E27 -> -0.64999996 | N28: =Numbers!F27 -> -0.40000002
B29: 1. | C29: Enter your Name: | D29: (Task: +100%) | E29: (Vision: +100%) | I29: Input | J29: have a craving to know more. Often they like to collect and archive all kinds of information. | M29: =Numbers!E28 -> 0.09999997 | N29: =Numbers!F28 -> 0.29999998
C30: Russell Crowe | D30: =MIN(1,MAX(-1,SUMPRODUCT($P$48:$P$55,N48:N55)/P60)) -> -1 | E30: =MIN(1,MAX(-1,SUMPRODUCT($P$48:$P$55,O48:O55)/P60)) -> -0.33333333 | I30: Intellection | J30: are characterized by their intellectual activity. They are introspective and appreciate intellectual discussions. | M30: =Numbers!E29 -> 0.87500002 | N30: =Numbers!F29 -> 0.875
I31: Learner | J31: have a great desire to learn and want to continuously improve. In particular, the process of learning, rather than the outcome, excites them. | M31: =Numbers!E30 -> 0.39999999 | N31: =Numbers!F30 -> -0.14999999
B32: 2. | C32: On a scale of 1 to 10 (where 1 means "one of my least preferred assignments", and 10 means | I32: Maximizer | J32: focus on strengths as a way to stimulate personal and group excellence. They seek to transform something strong into something superb. | M32: =Numbers!E31 -> 0.40000003 | N32: =Numbers!F31 -> 0.24999996
C33: "one of my most preferred assignments") rate each of the following hypothetical assignments: | I33: Positivity | J33: have an enthusiasm that is contagious. They are upbeat and can get others excited about what they are going to do. | M33: =Numbers!E32 -> -0.79999996 | N33: =Numbers!F32 -> 0.39999998
I34: Relator | J34: enjoy close relationships with others. They find deep sat- isfaction in working hard with friends to achieve a goal. | M34: =Numbers!E33 -> -0.44999996 | N34: =Numbers!F33 -> -0.13636364
C35: Hypothetical Assignment | D35: Rating | I35: Responsibility | J35: take psychological ownership of what they say they will do. They are committed to stable values such as honesty and loyalty. | M35: =Numbers!E34 -> 0.25000004 | N35: =Numbers!F34 -> -0.65000002
B36: A. | C36: Forecast future technology trends for your industry | D36: 4 | E36: =IF(AND(D36<=10,D36>=1),"","Should be between 1 and 10.") | I36: Restorative | J36: are adept at dealing with problems. They are good at figuring out what is wrong and resolving it. | M36: =Numbers!E35 -> -0.10000003 | N36: =Numbers!F35 -> 0.10000004
B37: B. | C37: Help each team member express their personal goals | D37: 5 | E37: =IF(AND(D37<=10,D37>=1),"","Should be between 1 and 10") | I37: Self-Assurance | J37: feel confident in their ability to manage their own lives. They possess an inner compass that gives them confidence that their decisions are right. | M37: =Numbers!E36 -> -0.46363636 | N37: =Numbers!F36 -> 0.79090907
B38: C. | C38: Plan training to suit the individual needs of all team members | D38: 7 | E38: =IF(AND(D38<=10,D38>=1),"","Should be between 1 and 10") | I38: Significance | J38: want to be very important in the eyes of others. They are independent and want to be recognized. | M38: =Numbers!E37 -> -0.13636363 | N38: =Numbers!F37 -> 0.40000005
B39: D. | C39: Reorganise and streamline the quality review process (whatever that might be) | D39: 4 | E39: =IF(AND(D39<=10,D39>=1),"","Should be between 1 and 10") | I39: Strategic | J39: create alternative ways to proceed. Faced with any given scenario, they can quickly spot the relevant patterns and issues. | M39: =Numbers!E38 -> 0.13636365 | N39: =Numbers!F38 -> 0.73636365
B40: E. | C40: Ensure everyone understands their highest priority task | D40: 6 | E40: =IF(AND(D40<=10,D40>=1),"","Should be between 1 and 10") | I40: Woo | J40: love the challenge of meeting new people and winning them over. They derive satisfaction from breaking the ice and making a connection with another. | M40: =Numbers!E39 -> -0.875 | N40: =Numbers!F39 -> -0.87499997
...

Sheet Team Analysis
A1: Team Analysis on Axes of People-Task and Execution-Vision
A2: © Bob Warfield 2015-2020
A4: 1. | B4: Enter the names (or nicknames) of your team - from 2 up to 10 members.
A6: 2. | B6: Enter their individual scores on the People-or-Task and Execution-or-Vision scales.
D9: (People: -100%) | E9: (Execution: -100%) | L9: 0.9 | M9: -0.9 | N9: -0.9 | O9: 0.9
D10: (Task: +100%) | E10: (Vision: +100%) | K10: =COUNTIF(K12:K21,"=true") -> 10 | L10: 0.9 | M10: 0.9 | N10: -0.9 | O10: -0.9
C11: Name | D11: People or Task | E11: Execution or Vision | W11: Task+Vision | X11: People+Vision | Y11: People+Execution | Z11: Task+Execution
C12: Russell Crowe | D12: -1 | E12: -0.33 | K12: =C12<>"" -> TRUE | L12: =IF($K12,(((L$9-$D12)^2 + (L$10-$E12)^2)),"") -> 5.1229 | M12: =IF($K12,(((M$9-$D12)^2 + (M$10-$E12)^2)),"") -> 1.5229 | N12: =IF($K12,(((N$9-$D12)^2 + (N$10-$E12)^2)),"") -> 0.3349 | O12: =IF($K12,(((O$9-$D12)^2 + (O$10-$E12)^2)),"") -> 3.9349 | Q12: =IF($K12,RANK(L24,L$24:L$33),"") -> 10 | R12: =IF($K12,RANK(M24,M$24:M$33),"") -> 6 | S12: =IF($K12,RANK(N24,N$24:N$33),"") -> 1 | T12: =IF($K12,RANK(O24,O$24:O$33),"") -> 7 | V12: 1 | W12: =IF($K12,MATCH($V12,Q$12:Q$21,0),"") -> 8 | X12: =IF($K12,MATCH($V12,R$12:R$21,0),"") -> 7 | Y12: =IF($K12,MATCH($V12,S$12:S$21,0),"") -> 1 | Z12: =IF($K12,MATCH($V12,T$12:T$21,0),"") -> 6
C13: Alaiya Anderson | D13: -0.19 | E13: -0.93 | K13: =C13<>"" -> TRUE | L13: =IF($K13,(((L$9-$D13)^2 + (L$10-$E13)^2)),"") -> 4.537 | M13: =IF($K13,(((M$9-$D13)^2 + (M$10-$E13)^2)),"") -> 3.853 | N13: =IF($K13,(((N$9-$D13)^2 + (N$10-$E13)^2)),"") -> 0.505 | O13: =IF($K13,(((O$9-$D13)^2 + (O$10-$E13)^2)),"") -> 1.189 | Q13: =IF($K13,RANK(L25,L$24:L$33),"") -> 9 | R13: =IF($K13,RANK(M25,M$24:M$33),"") -> 9 | S13: =IF($K13,RANK(N25,N$24:N$33),"") -> 2 | T13: =IF($K13,RANK(O25,O$24:O$33),"") -> 2 | V13: 2 | W13: =IF($K13,MATCH($V13,Q$12:Q$21,0),"") -> 3 | X13: =IF($K13,MATCH($V13,R$12:R$21,0),"") -> 4 | Y13: =IF($K13,MATCH($V13,S$12:S$21,0),"") -> 2 | Z13: =IF($K13,MATCH($V13,T$12:T$21,0),"") -> 2
C14: Oakleigh Davis | D14: 0.33 | E14: 0.52 | K14: =C14<>"" -> TRUE | L14: =IF($K14,(((L$9-$D14)^2 + (L$10-$E14)^2)),"") -> 0.4693 | M14: =IF($K14,(((M$9-$D14)^2 + (M$10-$E14)^2)),"") -> 1.6573 | N14: =IF($K14,(((N$9-$D14)^2 + (N$10-$E14)^2)),"") -> 3.5293 | O14: =IF($K14,(((O$9-$D14)^2 + (O$10-$E14)^2)),"") -> 2.3413 | Q14: =IF($K14,RANK(L26,L$24:L$33),"") -> 2 | R14: =IF($K14,RANK(M26,M$24:M$33),"") -> 7 | S14: =IF($K14,RANK(N26,N$24:N$33),"") -> 8 | T14: =IF($K14,RANK(O26,O$24:O$33),"") -> 4 | V14: 3 | W14: =IF($K14,MATCH($V14,Q$12:Q$21,0),"") -> 9 | X14: =IF($K14,MATCH($V14,R$12:R$21,0),"") -> 5 | Y14: =IF($K14,MATCH($V14,S$12:S$21,0),"") -> 10 | Z14: =IF($K14,MATCH($V14,T$12:T$21,0),"") -> 8
C15: Ainhoa Garcia | D15: -0.97 | E15: 0.46 | K15: =C15<>"" -> TRUE | L15: =IF($K15,(((L$9-$D15)^2 + (L$10-$E15)^2)),"") -> 3.6905 | M15: =IF($K15,(((M$9-$D15)^2 + (M$10-$E15)^2)),"") -> 0.1985 | N15: =IF($K15,(((N$9-$D15)^2 + (N$10-$E15)^2)),"") -> 1.8545 | O15: =IF($K15,(((O$9-$D15)^2 + (O$10-$E15)^2)),"") -> 5.3465 | Q15: =IF($K15,RANK(L27,L$24:L$33),"") -> 8 | R15: =IF($K15,RANK(M27,M$24:M$33),"") -> 2 | S15: =IF($K15,RANK(N27,N$24:N$33),"") -> 5 | T15: =IF($K15,RANK(O27,O$24:O$33),"") -> 9 | V15: 4 | W15: =IF($K15,MATCH($V15,Q$12:Q$21,0),"") -> 5 | X15: =IF($K15,MATCH($V15,R$12:R$21,0),"") -> 10 | Y15: =IF($K15,MATCH($V15,S$12:S$21,0),"") -> 5 | Z15: =IF($K15,MATCH($V15,T$12:T$21,0),"") -> 3
C16: Salem Harris | D16: -0.82 | E16: 0.23 | K16: =C16<>"" -> TRUE | L16: =IF($K16,(((L$9-$D16)^2 + (L$10-$E16)^2)),"") -> 3.4073 | M16: =IF($K16,(((M$9-$D16)^2 + (M$10-$E16)^2)),"") -> 0.4553 | N16: =IF($K16,(((N$9-$D16)^2 + (N$10-$E16)^2)),"") -> 1.2833 | O16: =IF($K16,(((O$9-$D16)^2 + (O$10-$E16)^2)),"") -> 4.2353 | Q16: =IF($K16,RANK(L28,L$24:L$33),"") -> 4 | R16: =IF($K16,RANK(M28,M$24:M$33),"") -> 3 | S16: =IF($K16,RANK(N28,N$24:N$33),"") -> 4 | T16: =IF($K16,RANK(O28,O$24:O$33),"") -> 8 | V16: 5 | W16: =IF($K16,MATCH($V16,Q$12:Q$21,0),"") -> 6 | X16: =IF($K16,MATCH($V16,R$12:R$21,0),"") -> 9 | Y16: =IF($K16,MATCH($V16,S$12:S$21,0),"") -> 4 | Z16: =IF($K16,MATCH($V16,T$12:T$21,0),"") -> 9
C17: Lyanna Jackson | D17: 0.47 | E17: -0.9 | K17: =C17<>"" -> TRUE | L17: =IF($K17,(((L$9-$D17)^2 + (L$10-$E17)^2)),"") -> 3.4249 | M17: =IF($K17,(((M$9-$D17)^2 + (M$10-$E17)^2)),"") -> 5.1169 | N17: =IF($K17,(((N$9-$D17)^2 + (N$10-$E17)^2)),"") -> 1.8769 | O17: =IF($K17,(((O$9-$D17)^2 + (O$10-$E17)^2)),"") -> 0.1849 | Q17: =IF($K17,RANK(L29,L$24:L$33),"") -> 5 | R17: =IF($K17,RANK(M29,M$24:M$33),"") -> 10 | S17: =IF($K17,RANK(N29,N$24:N$33),"") -> 6 | T17: =IF($K17,RANK(O29,O$24:O$33),"") -> 1 | V17: 6 | W17: =IF($K17,MATCH($V17,Q$12:Q$21,0),"") -> 7 | X17: =IF($K17,MATCH($V17,R$12:R$21,0),"") -> 1 | Y17: =IF($K17,MATCH($V17,S$12:S$21,0),"") -> 6 | Z17: =IF($K17,MATCH($V17,T$12:T$21,0),"") -> 10
C18: Kaisley Martin | D18: -0.96 | E18: 0.74 | K18: =C18<>"" -> TRUE | L18: =IF($K18,(((L$9-$D18)^2 + (L$10-$E18)^2)),"") -> 3.4852 | M18: =IF($K18,(((M$9-$D18)^2 + (M$10-$E18)^2)),"") -> 0.0292 | N18: =IF($K18,(((N$9-$D18)^2 + (N$10-$E18)^2)),"") -> 2.6932 | O18: =IF($K18,(((O$9-$D18)^2 + (O$10-$E18)^2)),"") -> 6.1492 | Q18: =IF($K18,RANK(L30,L$24:L$33),"") -> 6 | R18: =IF($K18,RANK(M30,M$24:M$33),"") -> 1 | S18: =IF($K18,RANK(N30,N$24:N$33),"") -> 7 | T18: =IF($K18,RANK(O30,O$24:O$33),"") -> 10 | V18: 7 | W18: =IF($K18,MATCH($V18,Q$12:Q$21,0),"") -> 10 | X18: =IF($K18,MATCH($V18,R$12:R$21,0),"") -> 3 | Y18: =IF($K18,MATCH($V18,S$12:S$21,0),"") -> 7 | Z18: =IF($K18,MATCH($V18,T$12:T$21,0),"") -> 1
C19: Liam Moore | D19: 0.97 | E19: 0.39 | K19: =C19<>"" -> TRUE | L19: =IF($K19,(((L$9-$D19)^2 + (L$10-$E19)^2)),"") -> 0.265 | M19: =IF($K19,(((M$9-$D19)^2 + (M$10-$E19)^2)),"") -> 3.757 | N19: =IF($K19,(((N$9-$D19)^2 + (N$10-$E19)^2)),"") -> 5.161 | O19: =IF($K19,(((O$9-$D19)^2 + (O$10-$E19)^2)),"") -> 1.669 | Q19: =IF($K19,RANK(L31,L$24:L$33),"") -> 1 | R19: =IF($K19,RANK(M31,M$24:M$33),"") -> 8 | S19: =IF($K19,RANK(N31,N$24:N$33),"") -> 10 | T19: =IF($K19,RANK(O31,O$24:O$33),"") -> 3 | V19: 8 | W19: =IF($K19,MATCH($V19,Q$12:Q$21,0),"") -> 4 | X19: =IF($K19,MATCH($V19,R$12:R$21,0),"") -> 8 | Y19: =IF($K19,MATCH($V19,S$12:S$21,0),"") -> 3 | Z19: =IF($K19,MATCH($V19,T$12:T$21,0),"") -> 5
C20: Noah Taylor | D20: 0.16 | E20: 0.89 | K20: =C20<>"" -> TRUE | L20: =IF($K20,(((L$9-$D20)^2 + (L$10-$E20)^2)),"") -> 0.5477 | M20: =IF($K20,(((M$9-$D20)^2 + (M$10-$E20)^2)),"") -> 1.1237 | N20: =IF($K20,(((N$9-$D20)^2 + (N$10-$E20)^2)),"") -> 4.3277 | O20: =IF($K20,(((O$9-$D20)^2 + (O$10-$E20)^2)),"") -> 3.7517 | Q20: =IF($K20,RANK(L32,L$24:L$33),"") -> 3 | R20: =IF($K20,RANK(M32,M$24:M$33),"") -> 5 | S20: =IF($K20,RANK(N32,N$24:N$33),"") -> 9 | T20: =IF($K20,RANK(O32,O$24:O$33),"") -> 5 | V20: 9 | W20: =IF($K20,MATCH($V20,Q$12:Q$21,0),"") -> 2 | X20: =IF($K20,MATCH($V20,R$12:R$21,0),"") -> 2 | Y20: =IF($K20,MATCH($V20,S$12:S$21,0),"") -> 9 | Z20: =IF($K20,MATCH($V20,T$12:T$21,0),"") -> 4
C21: William Thomas | D21: -0.81 | E21: 0.07 | K21: =C21<>"" -> TRUE | L21: =IF($K21,(((L$9-$D21)^2 + (L$10-$E21)^2)),"") -> 3.613 | M21: =IF($K21,(((M$9-$D21)^2 + (M$10-$E21)^2)),"") -> 0.697 | N21: =IF($K21,(((N$9-$D21)^2 + (N$10-$E21)^2)),"") -> 0.949 | O21: =IF($K21,(((O$9-$D21)^2 + (O$10-$E21)^2)),"") -> 3.865 | Q21: =IF($K21,RANK(L33,L$24:L$33),"") -> 7 | R21: =IF($K21,RANK(M33,M$24:M$33),"") -> 4 | S21: =IF($K21,RANK(N33,N$24:N$33),"") -> 3 | T21: =IF($K21,RANK(O33,O$24:O$33),"") -> 6 | V21: 10 | W21: =IF($K21,MATCH($V21,Q$12:Q$21,0),"") -> 1 | X21: =IF($K21,MATCH($V21,R$12:R$21,0),"") -> 6 | Y21: =IF($K21,MATCH($V21,S$12:S$21,0),"") -> 8 | Z21: =IF($K21,MATCH($V21,T$12:T$21,0),"") -> 7
L24: =IF($K12,IF(L12<1/10,10,1/L12),"") -> 0.19520194 | M24: =IF($K12,IF(M12<1/10,10,1/M12),"") -> 0.65664193 | N24: =IF($K12,IF(N12<1/10,10,1/N12),"") -> 2.985966 | O24: =IF($K12,IF(O12<1/10,10,1/O12),"") -> 0.25413606
B25: Here is a plot of the individuals in your team: | L25: =IF($K13,IF(L13<1/10,10,1/L13),"") -> 0.22040996 | M25: =IF($K13,IF(M13<1/10,10,1/M13),"") -> 0.25953802 | N25: =IF($K13,IF(N13<1/10,10,1/N13),"") -> 1.980198 | O25: =IF($K13,IF(O13<1/10,10,1/O13),"") -> 0.84104289
L26: =IF($K14,IF(L14<1/10,10,1/L14),"") -> 2.1308332 | M26: =IF($K14,IF(M14<1/10,10,1/M14),"") -> 0.60339106 | N26: =IF($K14,IF(N14<1/10,10,1/N14),"") -> 0.28334231 | O26: =IF($K14,IF(O14<1/10,10,1/O14),"") -> 0.42711314
L27: =IF($K15,IF(L15<1/10,10,1/L15),"") -> 0.27096599 | M27: =IF($K15,IF(M15<1/10,10,1/M15),"") -> 5.0377834 | N27: =IF($K15,IF(N15<1/10,10,1/N15),"") -> 0.5392289 | O27: =IF($K15,IF(O15<1/10,10,1/O15),"") -> 0.18703825
L28: =IF($K16,IF(L16<1/10,10,1/L16),"") -> 0.29348751 | M28: =IF($K16,IF(M16<1/10,10,1/M16),"") -> 2.1963541 | N28: =IF($K16,IF(N16<1/10,10,1/N16),"") -> 0.77924102 | O28: =IF($K16,IF(O16<1/10,10,1/O16),"") -> 0.23611078
L29: =IF($K17,IF(L17<1/10,10,1/L17),"") -> 0.29197933 | M29: =IF($K17,IF(M17<1/10,10,1/M17),"") -> 0.19543083 | N29: =IF($K17,IF(N17<1/10,10,1/N17),"") -> 0.53279344 | O29: =IF($K17,IF(O17<1/10,10,1/O17),"") -> 5.4083288 | V29: =X11 -> People+Vision | Z29: =W11 -> Task+Vision
L30: =IF($K18,IF(L18<1/10,10,1/L18),"") -> 0.28692758 | M30: =IF($K18,IF(M18<1/10,10,1/M18),"") -> 10 | N30: =IF($K18,IF(N18<1/10,10,1/N18),"") -> 0.37130551 | O30: =IF($K18,IF(O18<1/10,10,1/O18),"") -> 0.16262278 | V30: {=IF($K12,INDEX($C$12:$C$21,X12),"")} -> Kaisley Martin | W30: {=IF($K12,INDEX($M$24:$M$33,X12),"")} -> 10 | Z30: {=IF($K12,INDEX($C$12:$C$21,W12),"")} -> Liam Moore | AA30: {=IF($K12,INDEX($L$24:$L$33,W12),"")} -> 3.7735849
L31: =IF($K19,IF(L19<1/10,10,1/L19),"") -> 3.7735849 | M31: =IF($K19,IF(M19<1/10,10,1/M19),"") -> 0.26616982 | N31: =IF($K19,IF(N19<1/10,10,1/N19),"") -> 0.1937609 | O31: =IF($K19,IF(O19<1/10,10,1/O19),"") -> 0.59916117 | V31: {=IF($K13,INDEX($C$12:$C$21,X13),"")} -> Ainhoa Garcia | W31: {=IF($K13,INDEX($M$24:$M$33,X13),"")} -> 5.0377834 | Z31: {=IF($K13,INDEX($C$12:$C$21,W13),"")} -> Oakleigh Davis | AA31: {=IF($K13,INDEX($L$24:$L$33,W13),"")} -> 2.1308332
L32: =IF($K20,IF(L20<1/10,10,1/L20),"") -> 1.8258171 | M32: =IF($K20,IF(M20<1/10,10,1/M20),"") -> 0.88991724 | N32: =IF($K20,IF(N20<1/10,10,1/N20),"") -> 0.23106962 | O32: =IF($K20,IF(O20<1/10,10,1/O20),"") -> 0.26654583 | V32: {=IF($K14,INDEX($C$12:$C$21,X14),"")} -> Salem Harris | W32: {=IF($K14,INDEX($M$24:$M$33,X14),"")} -> 2.1963541 | Z32: {=IF($K14,INDEX($C$12:$C$21,W14),"")} -> Noah Taylor | AA32: {=IF($K14,INDEX($L$24:$L$33,W14),"")} -> 1.8258171
L33: =IF($K21,IF(L21<1/10,10,1/L21),"") -> 0.2767783 | M33: =IF($K21,IF(M21<1/10,10,1/M21),"") -> 1.4347202 | N33: =IF($K21,IF(N21<1/10,10,1/N21),"") -> 1.0537408 | O33: =IF($K21,IF(O21<1/10,10,1/O21),"") -> 0.25873221 | V33: {=IF($K15,INDEX($C$12:$C$21,X15),"")} -> William Thomas | W33: {=IF($K15,INDEX($M$24:$M$33,X15),"")} -> 1.4347202 | Z33: {=IF($K15,INDEX($C$12:$C$21,W15),"")} -> Salem Harris | AA33: {=IF($K15,INDEX($L$24:$L$33,W15),"")} -> 0.29348751
V34: {=IF($K16,INDEX($C$12:$C$21,X16),"")} -> Noah Taylor | W34: {=IF($K16,INDEX($M$24:$M$33,X16),"")} -> 0.88991724 | Z34: {=IF($K16,INDEX($C$12:$C$21,W16),"")} -> Lyanna Jackson | AA34: {=IF($K16,INDEX($L$24:$L$33,W16),"")} -> 0.29197933
V35: {=IF($K17,INDEX($C$12:$C$21,X17),"")} -> Russell Crowe | W35: {=IF($K17,INDEX($M$24:$M$33,X17),"")} -> 0.65664193 | Z35: {=IF($K17,INDEX($C$12:$C$21,W17),"")} -> Kaisley Martin | AA35: {=IF($K17,INDEX($L$24:$L$33,W17),"")} -> 0.28692758
L36: =L9/2 -> 0.45 | M36: =M9/2 -> -0.45 | N36: =N9/2 -> -0.45 | O36: =O9/2 -> 0.45 | V36: {=IF($K18,INDEX($C$12:$C$21,X18),"")} -> Oakleigh Davis | W36: {=IF($K18,INDEX($M$24:$M$33,X18),"")} -> 0.60339106 | Z36: {=IF($K18,INDEX($C$12:$C$21,W18),"")} -> William Thomas | AA36: {=IF($K18,INDEX($L$24:$L$33,W18),"")} -> 0.2767783
L37: =L10/2 -> 0.45 | M37: =M10/2 -> 0.45 | N37: =N10/2 -> -0.45 | O37: =O10/2 -> -0.45 | V37: {=IF($K19,INDEX($C$12:$C$21,X19),"")} -> Liam Moore | W37: {=IF($K19,INDEX($M$24:$M$33,X19),"")} -> 0.26616982 | Z37: {=IF($K19,INDEX($C$12:$C$21,W19),"")} -> Ainhoa Garcia | AA37: {=IF($K19,INDEX($L$24:$L$33,W19),"")} -> 0.27096599
L38: =(AVERAGE(L24:L33))^2 -> 0.91508083 | M38: =(AVERAGE(M24:M33))^2 -> 4.639693 | N38: =(AVERAGE(N24:N33))^2 -> 0.80114072 | O38: =(AVERAGE(O24:O33))^2 -> 0.74663977 | V38: {=IF($K20,INDEX($C$12:$C$21,X20),"")} -> Alaiya Anderson | W38: {=IF($K20,INDEX($M$24:$M$33,X20),"")} -> 0.25953802 | Z38: {=IF($K20,INDEX($C$12:$C$21,W20),"")} -> Alaiya Anderson | AA38: {=IF($K20,INDEX($L$24:$L$33,W20),"")} -> 0.22040996
L39: Task+Vision | M39: People+Vision | N39: People+Execution | O39: Task+Execution | V39: {=IF($K21,INDEX($C$12:$C$21,X21),"")} -> Lyanna Jackson | W39: {=IF($K21,INDEX($M$24:$M$33,X21),"")} -> 0.19543083 | Z39: {=IF($K21,INDEX($C$12:$C$21,W21),"")} -> Russell Crowe | AA39: {=IF($K21,INDEX($L$24:$L$33,W21),"")} -> 0.19520194
V44: =Y11 -> People+Execution | Z44: =Z11 -> Task+Execution
V45: {=IF($K12,INDEX($C$12:$C$21,Y12),"")} -> Russell Crowe | W45: {=IF($K12,INDEX($N$24:$N$33,Y12),"")} -> 2.985966 | Z45: {=IF($K12,INDEX($C$12:$C$21,Z12),"")} -> Lyanna Jackson | AA45: {=IF($K12,INDEX($O$24:$O$33,Z12),"")} -> 5.4083288
V46: {=IF($K13,INDEX($C$12:$C$21,Y13),"")} -> Alaiya Anderson | W46: {=IF($K13,INDEX($N$24:$N$33,Y13),"")} -> 1.980198 | Z46: {=IF($K13,INDEX($C$12:$C$21,Z13),"")} -> Alaiya Anderson | AA46: {=IF($K13,INDEX($O$24:$O$33,Z13),"")} -> 0.84104289
V47: {=IF($K14,INDEX($C$12:$C$21,Y14),"")} -> William Thomas | W47: {=IF($K14,INDEX($N$24:$N$33,Y14),"")} -> 1.0537408 | Z47: {=IF($K14,INDEX($C$12:$C$21,Z14),"")} -> Liam Moore | AA47: {=IF($K14,INDEX($O$24:$O$33,Z14),"")} -> 0.59916117
V48: {=IF($K15,INDEX($C$12:$C$21,Y15),"")} -> Salem Harris | W48: {=IF($K15,INDEX($N$24:$N$33,Y15),"")} -> 0.77924102 | Z48: {=IF($K15,INDEX($C$12:$C$21,Z15),"")} -> Oakleigh Davis | AA48: {=IF($K15,INDEX($O$24:$O$33,Z15),"")} -> 0.42711314
V49: {=IF($K16,INDEX($C$12:$C$21,Y16),"")} -> Ainhoa Garcia | W49: {=IF($K16,INDEX($N$24:$N$33,Y16),"")} -> 0.5392289 | Z49: {=IF($K16,INDEX($C$12:$C$21,Z16),"")} -> Noah Taylor | AA49: {=IF($K16,INDEX($O$24:$O$33,Z16),"")} -> 0.26654583
V50: {=IF($K17,INDEX($C$12:$C$21,Y17),"")} -> Lyanna Jackson | W50: {=IF($K17,INDEX($N$24:$N$33,Y17),"")} -> 0.53279344 | Z50: {=IF($K17,INDEX($C$12:$C$21,Z17),"")} -> William Thomas | AA50: {=IF($K17,INDEX($O$24:$O$33,Z17),"")} -> 0.25873221
...

Sheet Fun and Games
A1: Some Activities to Check Out the Theory
A2: © Bob Warfield 2015-2020
A5: 1. The "Changing a Lightbulb" Game for Analysing your Friends
A7: How many people in the Task+Vision Quadrant does it take to change a lightbulb?
A9: Task + Vision
B10: I'm not sure I can change the light bulb, because so many inventors have worked on it already. I'll start by reading up on the technology of lighting.
A12: How about the other three quadrants:
A14: People + Vision
B15: I'm glad you asked me that - I'm drawing up a roster for light-bulb changing. I'll post it on the fridge in the tea-room.
A17: People + Execution
B18: Oh, I'm so busy just now. Couldn't you please do it for me? I'll be your BFF if you do.
A20: Task + Execution
B21: One. I'm better on my own, thanks all the same.
A23: Play this game for yourself: select a challenging task - one that is a bit more arduous than changing a light bulb.
A24: Imagine how a person in each of the four quadrants would react to being asked to take on the task.
A25: Test your prediction on your friends - the ones who have revealed their People-Task Execution-Vision (PTEV) scores to you.
A32: 2. The "Stretch Exercise" Game for Improving on Non-Strengths
A34: If you want to improve your performance, focus on your strengths! That is the most efficient way to progress.
A35: How do you improve a strength - just do it. Do it your way.
A36: Let me say that another way: if you want to improve your performance don't dwell on your weaknesses, or "non-strengths".
A38: But if you really do want to improve one of your non-strengths, or "weaknesses", make it FUN! Craft a "Stretch Exercise" for yourself.
A40: How to craft a "Stretch Exercise":
B41: It must be out of your normal work routine.
B42: It must be outside your comfort zone.
B43: It must be safe - no unmanaged risks to you or the general public.
B44: It must be blame-free - there is no "fail", there is only "learn and try again".
B45: It has to be fun. Or just move on to something else. Life is too long and miserable as it is.
A47: For example, suppose you can't swim. You cannot even stand to put your face underwater.
B48: How about: "Let's go to the end of the jetty and jump into the ocean, then we have to swim."
B49: Nope.
B50: What about: "Get a book on champion swimmers and read that."
B51: You're not getting it.
B52: How about: "When we have a shower, deliberately put our face in the stream of water and sing a happy song. Remember to breathe."
B53: That's much better, and how about adding: "Go to the swimming pool and dip our face in the water and sing our happy song."
B54: That's it.
B55: But what if someone laughs at us for being silly?
B56: You're too important to be distracted by them. Focus your attention on the people who support you. In fact, the mockers can go jump in the pool!
B57: And that is how you make improving a "weakness" fun!
A59: Here's another example, more to the point of a work environment: "I find it hard to converse with people I don't know"
B60: Not only do I find it hard, my stomach has a way of telling me I cannot do it. Also the blood circulation to my face makes me want to go away, now.
...

Sheet Numbers
E1: =MIN(E6:E39) -> -0.87500002 | F1: =MAX(F6:F39) -> 0.875
E3: =Self_Assessment!D30 -> -1 | F3: =Self_Assessment!E30 -> -0.33333333 | M3: People who are especially talented in the
B5: Strength | C5: Xi | D5: eta | E5: task | F5: vision | G5: dˆ2 | H5: rank | J5: best_worst | K5: match | L5: Theme
A6: have a great deal of stamina and work hard. They take great satisfaction from being busy and productive. | B6: Achiever | C6: 1.875 | D6: 0.125 | E6: =(C6-1)+0.0000001*(RAND()-0.5) -> 0.875 | F6: =(D6-1)+0.0000001*(RAND()-0.5) -> -0.87499996 | G6: =(E6-$E$3)^2+(F6-$F$3)^2 -> 3.8090277 | H6: =RANK(G6,$G$6:$G$39) -> 3 | J6: 34 | K6: =MATCH(J6,$H$6:$H$39,0) -> 22 | L6: =INDEX($B$6:$B$39,K6) -> Individualization | M6: =$M$3&L6&" theme "&INDEX($A$6:$A$39,K6) -> People who are especially talented in the Individualization theme are intrigued with the unique qualities of each person. They have a gift for figuring out how people who are different can work together productively.
A7: can make things happen by turning thoughts into action. They are often impatient. | B7: Activator | C7: 1.7 | D7: 0.4 | E7: =(C7-1)+0.0000001*(RAND()-0.5) -> 0.70000004 | F7: =(D7-1)+0.0000001*(RAND()-0.5) -> -0.59999996 | G7: =(E7-$E$3)^2+(F7-$F$3)^2 -> 2.9611112 | H7: =RANK(G7,$G$6:$G$39) -> 6 | J7: 33 | K7: =MATCH(J7,$H$6:$H$39,0) -> 19 | L7: =INDEX($B$6:$B$39,K7) -> Harmony | M7: =$M$3&L7&" theme "&INDEX($A$6:$A$39,K7) -> People who are especially talented in the Harmony theme look for consensus. They don’t enjoy conflict; rather, they seek areas of agreement.
A8: prefer to “go with the flow.” They tend to be “now” people who take things as they come and discover the future one day at a time. | B8: Adaptability | C8: 1.35 | D8: 0.7 | E8: =(C8-1)+0.0000001*(RAND()-0.5) -> 0.34999998 | F8: =(D8-1)+0.0000001*(RAND()-0.5) -> -0.29999995 | G8: =(E8-$E$3)^2+(F8-$F$3)^2 -> 1.8236111 | H8: =RANK(G8,$G$6:$G$39) -> 12 | J8: 32 | K8: =MATCH(J8,$H$6:$H$39,0) -> 34 | L8: =INDEX($B$6:$B$39,K8) -> Woo | M8: =$M$3&L8&" theme "&INDEX($A$6:$A$39,K8) -> People who are especially talented in the Woo theme love the challenge of meeting new people and winning them over. They derive satisfaction from breaking the ice and making a connection with another.
A9: search for reasons and causes. They have the ability to think about all the factors that might affect a situation. | B9: Analytical | C9: 1.7 | D9: 1.4 | E9: =(C9-1)+0.0000001*(RAND()-0.5) -> 0.70000004 | F9: =(D9-1)+0.0000001*(RAND()-0.5) -> 0.4 | G9: =(E9-$E$3)^2+(F9-$F$3)^2 -> 3.4277779 | H9: =RANK(G9,$G$6:$G$39) -> 4
A10: can organize, but they also have a flexibility that complements this ability. They like to figure out how all of the pieces and resources can be arranged for maximum productivity. | B10: Arranger | C10: 0.88 | D10: 0.65 | E10: =(C10-1)+0.0000001*(RAND()-0.5) -> -0.12000001 | F10: =(D10-1)+0.0000001*(RAND()-0.5) -> -0.34999999 | G10: =(E10-$E$3)^2+(F10-$F$3)^2 -> 0.77467776 | H10: =RANK(G10,$G$6:$G$39) -> 25 | J10: 1 | K10: =MATCH(J10,$H$6:$H$39,0) -> 24 | L10: =INDEX($B$6:$B$39,K10) -> Intellection | M10: =$M$3&L10&" theme "&INDEX($A$6:$A$39,K10) -> People who are especially talented in the Intellection theme are characterized by their intellectual activity. They are introspective and appreciate intellectual discussions.
A11: have certain core values that are unchanging. Out of these values emerges a defined purpose for their life. | B11: Belief | C11: 0.125 | D11: 1.875 | E11: =(C11-1)+0.0000001*(RAND()-0.5) -> -0.87500002 | F11: =(D11-1)+0.0000001*(RAND()-0.5) -> 0.87499999 | G11: =(E11-$E$3)^2+(F11-$F$3)^2 -> 1.4756944 | H11: =RANK(G11,$G$6:$G$39) -> 18 | J11: 2 | K11: =MATCH(J11,$H$6:$H$39,0) -> 18 | L11: =INDEX($B$6:$B$39,K11) -> Futuristic | M11: =$M$3&L11&" theme "&INDEX($A$6:$A$39,K11) -> People who are especially talented in the Futuristic theme are inspired by the future and what could be. They inspire others with their visions of the future.
A12: have presence. They can take control of a situation and make decisions. | B12: Command | C12: 1.1 | D12: 0.15454545 | E12: =(C12-1)+0.0000001*(RAND()-0.5) -> 0.10000001 | F12: =(D12-1)+0.0000001*(RAND()-0.5) -> -0.84545455 | G12: =(E12-$E$3)^2+(F12-$F$3)^2 -> 1.4722682 | H12: =RANK(G12,$G$6:$G$39) -> 19 | J12: 3 | K12: =MATCH(J12,$H$6:$H$39,0) -> 1 | L12: =INDEX($B$6:$B$39,K12) -> Achiever | M12: =$M$3&L12&" theme "&INDEX($A$6:$A$39,K12) -> People who are especially talented in the Achiever theme have a great deal of stamina and work hard. They take great satisfaction from being busy and productive.
A13: generally find it easy to put their thoughts into words. They are good conversationalists and presenters. | B13: Communication | C13: 0.6 | D13: 0.75454545 | E13: =(C13-1)+0.0000001*(RAND()-0.5) -> -0.39999998 | F13: =(D13-1)+0.0000001*(RAND()-0.5) -> -0.24545453 | G13: =(E13-$E$3)^2+(F13-$F$3)^2 -> 0.36772271 | H13: =RANK(G13,$G$6:$G$39) -> 30
A14: measure their progress against the performance of others. They strive to win first place and revel in contests. | B14: Competition | C14: 1.1909091 | D14: 1.4090909 | E14: =(C14-1)+0.0000001*(RAND()-0.5) -> 0.19090907 | F14: =(D14-1)+0.0000001*(RAND()-0.5) -> 0.40909094 | G14: =(E14-$E$3)^2+(F14-$F$3)^2 -> 1.9694582 | H14: =RANK(G14,$G$6:$G$39) -> 11
A15: have faith in the links between all things. They believe there are few coincidences and that almost every event has a reason. | B15: Connectedness | C15: 0.2 | D15: 1.7 | E15: =(C15-1)+0.0000001*(RAND()-0.5) -> -0.8 | F15: =(D15-1)+0.0000001*(RAND()-0.5) -> 0.69999999 | G15: =(E15-$E$3)^2+(F15-$F$3)^2 -> 1.1077778 | H15: =RANK(G15,$G$6:$G$39) -> 22
A16: are keenly aware of the need to treat people the same. They try to treat everyone in the world with consistency by setting up clear rules and adhering to them. | B16: Consistency | C16: 0.7 | D16: 0.95 | E16: =(C16-1)+0.0000001*(RAND()-0.5) -> -0.3 | F16: =(D16-1)+0.0000001*(RAND()-0.5) -> -0.049999991 | G16: =(E16-$E$3)^2+(F16-$F$3)^2 -> 0.57027779 | H16: =RANK(G16,$G$6:$G$39) -> 27
A17: enjoy thinking about the past. They understand the present by researching its history. | B17: Context | C17: 1.15 | D17: 0.64545455 | E17: =(C17-1)+0.0000001*(RAND()-0.5) -> 0.15000003 | F17: =(D17-1)+0.0000001*(RAND()-0.5) -> -0.35454542 | G17: =(E17-$E$3)^2+(F17-$F$3)^2 -> 1.32295 | H17: =RANK(G17,$G$6:$G$39) -> 20
A18: are best described by the serious care they take in making decisions or choices. They anticipate the obstacles. | B18: Deliberative | C18: 1.1 | D18: 1.1909091 | E18: =(C18-1)+0.0000001*(RAND()-0.5) -> 0.10000001 | F18: =(D18-1)+0.0000001*(RAND()-0.5) -> 0.19090908 | G18: =(E18-$E$3)^2+(F18-$F$3)^2 -> 1.4848301 | H18: =RANK(G18,$G$6:$G$39) -> 17
A19: recognize and cultivate the potential in others. They spot the signs of each small improvement and derive satisfaction from these improvements. | B19: Developer | C19: 0.7 | D19: 1.3 | E19: =(C19-1)+0.0000001*(RAND()-0.5) -> -0.30000005 | F19: =(D19-1)+0.0000001*(RAND()-0.5) -> 0.30000001 | G19: =(E19-$E$3)^2+(F19-$F$3)^2 -> 0.89111105 | H19: =RANK(G19,$G$6:$G$39) -> 24
A20: enjoy routine and structure. Their world is best de- scribed by the order they create. | B20: Discipline | C20: 1.7 | D20: 0.7 | E20: =(C20-1)+0.0000001*(RAND()-0.5) -> 0.69999999 | F20: =(D20-1)+0.0000001*(RAND()-0.5) -> -0.29999996 | G20: =(E20-$E$3)^2+(F20-$F$3)^2 -> 2.8911111 | H20: =RANK(G20,$G$6:$G$39) -> 7
A21: can sense the feelings of other people by imagining themselves in others’ lives or others’ situations. | B21: Empathy | C21: 0.55 | D21: 1.0818182 | E21: =(C21-1)+0.0000001*(RAND()-0.5) -> -0.44999996 | F21: =(D21-1)+0.0000001*(RAND()-0.5) -> 0.08181817 | G21: =(E21-$E$3)^2+(F21-$F$3)^2 -> 0.47485082 | H21: =RANK(G21,$G$6:$G$39) -> 29
A22: can take a direction, follow through, and make the corrections necessary to stay on track. They prioritize, then act. | B22: Focus | C22: 1.2 | D22: 0.91818182 | E22: =(C22-1)+0.0000001*(RAND()-0.5) -> 0.20000001 | F22: =(D22-1)+0.0000001*(RAND()-0.5) -> -0.081818176 | G22: =(E22-$E$3)^2+(F22-$F$3)^2 -> 1.5032599 | H22: =RANK(G22,$G$6:$G$39) -> 16
A23: are inspired by the future and what could be. They inspire others with their visions of the future. | B23: Futuristic | C23: 1.8 | D23: 1.7 | E23: =(C23-1)+0.0000001*(RAND()-0.5) -> 0.80000002 | F23: =(D23-1)+0.0000001*(RAND()-0.5) -> 0.70000001 | G23: =(E23-$E$3)^2+(F23-$F$3)^2 -> 4.3077779 | H23: =RANK(G23,$G$6:$G$39) -> 2
A24: look for consensus. They don’t enjoy conflict; rather, they seek areas of agreement. | B24: Harmony | C24: 0.42727273 | D24: 0.4 | E24: =(C24-1)+0.0000001*(RAND()-0.5) -> -0.57272728 | F24: =(D24-1)+0.0000001*(RAND()-0.5) -> -0.60000004 | G24: =(E24-$E$3)^2+(F24-$F$3)^2 -> 0.25367311 | H24: =RANK(G24,$G$6:$G$39) -> 33
... A39: love the challenge of meeting new people and winning them over. They derive satisfaction from breaking the ice and making a connection with another. | B39: Woo | C39: 0.125 | D39: 0.125 | E39: =(C39-1)+0.0000001*(RAND()-0.5) -> -0.875 | F39: =(D39-1)+0.0000001*(RAND()-0.5) -> -0.87499997 | G39: =(E39-$E$3)^2+(F39-$F$3)^2 -> 0.30902774 | H39: =RANK(G39,$G$6:$G$39) -> 32
B44: Occupation | C44: Xi | D44: eta | E44: task | F44: vision | G44: dˆ2 | H44: rank | J44: best_worst | K44: match | L44: Occupation
B45: Architect | C45: 1.8083946 | D45: 1.334848 | E45: =(C45-1)+0.0000001*(RAND()-0.5) -> 0.80839457 | F45: =(D45-1)+0.0000001*(RAND()-0.5) -> 0.33484797 | G45: =(E45-$E$3)^2+(F45-$F$3)^2 -> 3.7167572 | H45: =RANK(G45,$G$45:$G$57) -> 1 | J45: 13 | K45: =MATCH(J45,$H$45:$H$57,0) -> 5 | L45: =INDEX($B$45:$B$57,K45) -> Actor
B46: Philosopher | C46: 1.334848 | D46: 1.8083946 | E46: =(C46-1)+0.0000001*(RAND()-0.5) -> 0.33484804 | F46: =(D46-1)+0.0000001*(RAND()-0.5) -> 0.80839458 | G46: =(E46-$E$3)^2+(F46-$F$3)^2 -> 3.0853619 | H46: =RANK(G46,$G$45:$G$57) -> 3 | J46: 12 | K46: =MATCH(J46,$H$45:$H$57,0) -> 12 | L46: =INDEX($B$45:$B$57,K46) -> Teacher
B47: Politician | C47: 0.665152 | D47: 1.8083946 | E47: =(C47-1)+0.0000001*(RAND()-0.5) -> -0.33484802 | F47: =(D47-1)+0.0000001*(RAND()-0.5) -> 0.80839461 | G47: =(E47-$E$3)^2+(F47-$F$3)^2 -> 1.7459698 | H47: =RANK(G47,$G$45:$G$57) -> 7 | J47: 11 | K47: =MATCH(J47,$H$45:$H$57,0) -> 4 | L47: =INDEX($B$45:$B$57,K47) -> Philanthropist
B48: Philanthropist | C48: 0.19160541 | D48: 1.334848 | E48: =(C48-1)+0.0000001*(RAND()-0.5) -> -0.80839454 | F48: =(D48-1)+0.0000001*(RAND()-0.5) -> 0.33484801 | G48: =(E48-$E$3)^2+(F48-$F$3)^2 -> 0.48317897 | H48: =RANK(G48,$G$45:$G$57) -> 11
B49: Actor | C49: 0.19160541 | D49: 0.665152 | E49: =(C49-1)+0.0000001*(RAND()-0.5) -> -0.80839463 | F49: =(D49-1)+0.0000001*(RAND()-0.5) -> -0.33484799 | G49: =(E49-$E$3)^2+(F49-$F$3)^2 -> 0.036714911 | H49: =RANK(G49,$G$45:$G$57) -> 13 | J49: 1 | K49: =MATCH(J49,$H$45:$H$57,0) -> 1 | L49: =INDEX($B$45:$B$57,K49) -> Architect
B50: Salesman | C50: 0.665152 | D50: 0.19160541 | E50: =(C50-1)+0.0000001*(RAND()-0.5) -> -0.33484805 | F50: =(D50-1)+0.0000001*(RAND()-0.5) -> -0.80839456 | G50: =(E50-$E$3)^2+(F50-$F$3)^2 -> 0.66811028 | H50: =RANK(G50,$G$45:$G$57) -> 10 | J50: 2 | K50: =MATCH(J50,$H$45:$H$57,0) -> 8 | L50: =INDEX($B$45:$B$57,K50) -> Farmer
B51: Builder | C51: 1.334848 | D51: 0.19160541 | E51: =(C51-1)+0.0000001*(RAND()-0.5) -> 0.334848 | F51: =(D51-1)+0.0000001*(RAND()-0.5) -> -0.80839459 | G51: =(E51-$E$3)^2+(F51-$F$3)^2 -> 2.0075024 | H51: =RANK(G51,$G$45:$G$57) -> 5 | J51: 3 | K51: =MATCH(J51,$H$45:$H$57,0) -> 2 | L51: =INDEX($B$45:$B$57,K51) -> Philosopher
B52: Farmer | C52: 1.8083946 | D52: 0.665152 | E52: =(C52-1)+0.0000001*(RAND()-0.5) -> 0.80839454 | F52: =(D52-1)+0.0000001*(RAND()-0.5) -> -0.33484799 | G52: =(E52-$E$3)^2+(F52-$F$3)^2 -> 3.2702931 | H52: =RANK(G52,$G$45:$G$57) -> 2
B53: Generalist | C53: 1 | D53: 1 | E53: =(C53-1)+0.0000001*(RAND()-0.5) -> -1.6834222e-08 | F53: =(D53-1)+0.0000001*(RAND()-0.5) -> -1.4438784e-08 | G53: =(E53-$E$3)^2+(F53-$F$3)^2 -> 1.1111111 | H53: =RANK(G53,$G$45:$G$57) -> 8
B54: Scientist | C54: 1.3535534 | D54: 1.3535534 | E54: =(C54-1)+0.0000001*(RAND()-0.5) -> 0.35355339 | F54: =(D54-1)+0.0000001*(RAND()-0.5) -> 0.35355343 | G54: =(E54-$E$3)^2+(F54-$F$3)^2 -> 2.3039202 | H54: =RANK(G54,$G$45:$G$57) -> 4
B55: Lawyer | C55: 0.64644661 | D55: 1.3535534 | E55: =(C55-1)+0.0000001*(RAND()-0.5) -> -0.35355338 | F55: =(D55-1)+0.0000001*(RAND()-0.5) -> 0.35355344 | G55: =(E55-$E$3)^2+(F55-$F$3)^2 -> 0.88970666 | H55: =RANK(G55,$G$45:$G$57) -> 9
B56: Teacher | C56: 0.64644661 | D56: 0.64644661 | E56: =(C56-1)+0.0000001*(RAND()-0.5) -> -0.35355343 | F56: =(D56-1)+0.0000001*(RAND()-0.5) -> -0.3535534 | G56: =(E56-$E$3)^2+(F56-$F$3)^2 -> 0.41830202 | H56: =RANK(G56,$G$45:$G$57) -> 12
B57: Cook | C57: 1.3535534 | D57: 0.64644661 | E57: =(C57-1)+0.0000001*(RAND()-0.5) -> 0.35355335 | F57: =(D57-1)+0.0000001*(RAND()-0.5) -> -0.3535534 | G57: =(E57-$E$3)^2+(F57-$F$3)^2 -> 1.8325155 | H57: =RANK(G57,$G$45:$G$57) -> 6
